<?xml version='1.0'?>
<sdf version='1.4'>
    <model name="my_robot">
        <static>false</static>
        <self_collide>1</self_collide>
        <link name='chassis'>
            <pose>0 0 .05 0 0 0</pose>
            <inertial>
                <mass>50</mass>
            </inertial>
            <collision name='collision'>
                <geometry>
                    <cylinder>
                        <radius>.5</radius>
                        <length>.1</length>
                    </cylinder>
                </geometry>
            </collision>

            <visual name='visual'>
                <geometry>
                    <cylinder>
                        <radius>.5</radius>
                        <length>.1</length>
                    </cylinder>
                </geometry>
            </visual>
        </link>
        <link name='arm1'>
            <pose>0 0 .125 0 0 0</pose>
            <inertial>
                <mass>.05</mass>
            </inertial>
            <collision name='collision'>
                <geometry>
                    <cylinder>
                        <radius>.1</radius>
                        <length>.05</length>
                    </cylinder>
                </geometry>
            </collision>

            <visual name='visual'>
                <geometry>
                    <cylinder>
                        <radius>.1</radius>
                        <length>.05</length>
                    </cylinder>
                </geometry>
            </visual>
        </link>
        <link name='arm2'> 
            <pose>0 0 1.15 0 0 0</pose>
            <inertial>
                <mass>0.5</mass>
            </inertial>
            <collision name='collision'>
                <geometry>
                    <cylinder>
                        <radius>.05</radius>
                        <length>2.0</length>
                    </cylinder>
                </geometry>
            </collision>

            <visual name='visual'>
                <geometry>
                    <cylinder>
                        <radius>.05</radius>
                        <length>2.0</length>
                    </cylinder>
                </geometry>
            </visual>
        </link>
        <link name="arm3"> 
            <pose>0 0 2.65 0 0 0</pose>
            <inertial>
                <mass>0.25</mass>
            </inertial>
            <collision name="collision">
                <geometry>
                    <cylinder>
                        <radius>.05</radius>
                        <length>1</length>
                    </cylinder>
                </geometry>
            </collision>
            <visual name="visual">
                <geometry>
                    <cylinder>
                        <radius>.05</radius>
                        <length>1</length>
                    </cylinder>
                </geometry>
            </visual>
        </link>
        <link name="arm4"> 
            <pose>0 0 3.4 0 0 0</pose>
            <inertial>
                <mass>.125</mass>
            </inertial>
            <collision name="collision">
                <geometry>
                    <cylinder>
                        <radius>.05</radius>
                        <length>0.5</length>
                    </cylinder>
                </geometry>
            </collision>
            <visual name="visual">
                <geometry>
                    <cylinder>
                        <radius>.05</radius>
                        <length>0.5</length>
                    </cylinder>
                </geometry>
            </visual>
        </link>
        <link name="arm5"> 
            <pose>0 0 3.675 0 0 0</pose>
            <inertial>
                <mass>.005</mass>
            </inertial>
            <collision name="collision">
                <geometry>
                    <cylinder>
                        <radius>.05</radius>
                        <length>.05</length>
                    </cylinder>
                </geometry>
            </collision>
            <visual name="visual">
                <geometry>
                    <cylinder>
                        <radius>.05</radius>
                        <length>.05</length>
                    </cylinder>
                </geometry>
            </visual>
        </link>
        <link name="palm"> 
            <pose>0 0 3.72 0 0 0</pose>
            <inertial>
                <mass>.005</mass>
            </inertial>
            <collision name="collision">
                <geometry>
                    <box>
                        <size>.15 .3 .04</size>
                    </box>
                </geometry>
            </collision>
            <visual name="visual">
                <geometry>
                    <box>
                        <size>.15 .3 .04</size>
                    </box>
                </geometry>
            </visual>
        </link>
        <link name="leftfinger"> 
            <pose>0 0.14 3.89 0 0 0</pose>
            <inertial>
                <mass>.005</mass>
            </inertial>
            <collision name="collision">
                <geometry>
                    <box>
                        <size>.15 .02 .3</size>
                    </box>
                </geometry>
                <surface>
                    <friction>
                        <ode>
                            <mu>500</mu>
                            <mu2>500</mu2>
                            <slip1>0.0</slip1>
                            <slip2>0.0</slip2>
                        </ode>
                    </friction>
                    <contact>
                        <ode>
                            <min_depth>5</min_depth>
                            <kp>1e8</kp>
                        </ode>
                    </contact>
                </surface>
            </collision>
            <visual name="visual">
                <geometry>
                    <box>
                        <size>.15 .02 .3</size>
                    </box>
                </geometry>
            </visual>
        </link>
        <link name="rightfinger"> 
            <pose>0 -0.14 3.89 0 0 0</pose>
            <inertial>
                <mass>.005</mass>
            </inertial>
            <collision name="collision">
                <geometry>
                    <box>
                        <size>.15 .02 .3</size>
                    </box>
                </geometry>
                <surface>
                    <friction>
                        <ode>
                            <mu>500</mu>
                            <mu2>500</mu2>
                            <slip1>0.0</slip1>
                            <slip2>0.0</slip2>
                        </ode>
                    </friction>
                     <contact>
                        <ode>
                            <min_depth>5</min_depth>
                            <kp>1e8</kp>
                        </ode>
                    </contact>
                </surface>
            </collision>
            <visual name="visual">
                <geometry>
                    <box>
                        <size>.15 .02 .3</size>
                    </box>
                </geometry>
            </visual>
        </link>
        <joint type="revolute" name="chasis_arm1_joint">
            <pose>0 0 -0.025 0 0 0</pose>
            <child>arm1</child>
            <parent>chassis</parent>
            <axis>
                <xyz>0 0 1</xyz>
                <dynamics>
                    <damping>2.0</damping>
                    <friction>0.7</friction>
                </dynamics>
                <limit>
                    <effort>100</effort>
                    <velocity>1.0</velocity>
                </limit>
            </axis>
        </joint>
        <joint type="revolute" name="arm1_arm2_joint">
            <pose>0 0 -1 0 0 0</pose>
            <child>arm2</child>
            <parent>arm1</parent>
            <axis>
                <xyz>1 0 0</xyz>
                <dynamics>
                    <damping>1.0</damping>
                    <friction>0.3</friction>
                </dynamics>
                <limit>
                    <lower>-1.0</lower>
                    <upper>1.0</upper>
                    <effort>100</effort>
                    <velocity>1.0</velocity>
                </limit>
            </axis>
        </joint>
        <joint name="arm2_arm3_joint" type="revolute">
            <parent> arm2 </parent>
            <child> arm3 </child>
            <pose> 0 0 -0.5 0 0 0</pose>
            <axis>
                <xyz> 1 0 0  </xyz>
                <dynamics>
                    <damping>1.0</damping>
                    <friction>0.3</friction>
                </dynamics>
                <limit>
                    <effort>100</effort>
                    <velocity>1.0</velocity>
                </limit>
            </axis>
        </joint>
        <joint name="arm3_arm4_joint" type="revolute">
            <parent> arm3 </parent>
            <child> arm4 </child>
            <pose> 0 0 -0.25 0 0 0</pose>
            <axis>
                <xyz> 1 0 0  </xyz>
                <dynamics>
                    <damping>1.0</damping>
                    <friction>0.3</friction>
                </dynamics>
                <limit>
                    <effort>100</effort>
                    <velocity>1.0</velocity>
                </limit>
            </axis>
        </joint>
        <joint name="arm4_arm5_joint" type="revolute">
            <parent> arm4 </parent>
            <child> arm5 </child>
            <pose> 0 0 -0.025 0 0 0</pose>
            <axis>
                <xyz> 0 0 1  </xyz>
                <dynamics>
                    <damping>1.0</damping>
                    <friction>0.3</friction>
                </dynamics>
                <limit>
                    <effort>100</effort>
                    <velocity>1.0</velocity>
                </limit>
            </axis>
        </joint>
        <joint name="arm5_palm_joint" type="revolute">
            <parent> arm5 </parent>
            <child> palm </child>
            <pose> 0 0 -0.02 0 0 0</pose>
            <axis>
                <xyz> 1 0 0  </xyz>
                <dynamics>
                    <damping>1.0</damping>
                    <friction>0.3</friction>
                </dynamics>
                <limit>
                    <effort>100</effort>
                    <velocity>1.0</velocity>
                </limit>
            </axis>
        </joint>
        <joint name="palm_leftfinger_joint" type="revolute">
            <parent> palm </parent>
            <child> leftfinger </child>
            <pose> 0 0 -0.15 0 0 0</pose>
            <axis>
                <xyz> 1 0 0</xyz>
                <dynamics>
                    <damping>1.0</damping>
                    <friction>0.3</friction>
                </dynamics>
                <limit>
                    <lower>-0.7</lower>
                    <upper>0.7</upper>
                    <effort>100</effort>
                    <velocity>1.0</velocity>
                </limit>
            </axis>
        </joint>
        <joint name="palm_rightfinger_joint" type="revolute">
            <parent> palm </parent>
            <child> rightfinger </child>
            <pose> 0 0 -0.15 0 0 0</pose>
            <axis>
                <xyz> 1 0 0 </xyz>
                <dynamics>
                    <damping>1.0</damping>
                    <friction>0.3</friction>
                </dynamics>
                <limit>
                    <lower>-0.7</lower>
                    <upper>0.7</upper>
                    <effort>100</effort>
                    <velocity>1.0</velocity>
                </limit>
            </axis>
        </joint> 
    </model>
</sdf>